<?xml version="1.0"?>
<robot xmlns:xacro="http://www.ros.org/wiki/xacro">

  <xacro:macro name="robot_core">

    <!-- ================= BASE ================= -->
    <link name="base_link">
      <collision>
        <geometry>
          <box size="0.1 0.1 0.1"/>
        </geometry>
      </collision>
    </link>

    <link name="chassis_link">
      <visual>
        <geometry>
          <box size="1 1 1"/>
        </geometry>
        <material name="red">
          <color rgba="1 0 0 1"/>
        </material>
      </visual>

      <collision>
        <geometry>
          <box size="1 1 1"/>
        </geometry>
      </collision>

      <inertial>
        <mass value="2.0"/>
        <origin xyz="0 0 0"/>
        <inertia
          ixx="0.1" ixy="0.0" ixz="0.0"
          iyy="0.1" iyz="0.0"
          izz="0.1"/>
      </inertial>
    </link>

    <joint name="base_to_chassis" type="fixed">
      <parent link="base_link"/>
      <child link="chassis_link"/>
      <origin xyz="0 0 0.5"/>
    </joint>

    <!-- ================= SHOULDER ================= -->
    <link name="shoulder">
      <visual>
        <origin xyz="0 0 0.15"/>
        <geometry>
          <cylinder length="0.3" radius="0.1"/>
        </geometry>
      </visual>
      <collision>
        <origin xyz="0 0 0.15"/>
        <geometry>
          <cylinder length="0.3" radius="0.1"/>
        </geometry>
      </collision>
      <inertial>
        <mass value="1.0"/>
        <origin xyz="0 0 0.15"/>
        <inertia
          ixx="0.01" ixy="0.0" ixz="0.0"
          iyy="0.01" iyz="0.0"
          izz="0.01"/>
      </inertial>
    </link>

    <joint name="shoulder_joint" type="revolute">
      <parent link="chassis_link"/>
      <child link="shoulder"/>
      <origin xyz="0 0 0.5"/>
      <axis xyz="0 0 1"/>
      <limit lower="-3.14" upper="3.14" effort="10" velocity="1"/>
    </joint>

    <!-- ================= ELBOW ================= -->
    <link name="elbow_link">
      <visual>
        <origin xyz="0 0 0.2"/>
        <geometry>
          <cylinder length="0.4" radius="0.08"/>
        </geometry>
      </visual>
      <collision>
        <origin xyz="0 0 0.2"/>
        <geometry>
          <cylinder length="0.4" radius="0.08"/>
        </geometry>
      </collision>
      <inertial>
        <mass value="0.5"/>
        <origin xyz="0 0 0.2"/>
        <inertia
          ixx="0.01" ixy="0.0" ixz="0.0"
          iyy="0.01" iyz="0.0"
          izz="0.01"/>
      </inertial>
    </link>

    <joint name="elbow_link_joint" type="revolute">
      <parent link="shoulder"/>
      <child link="elbow_link"/>
      <origin xyz="0 0 0.3"/>
      <axis xyz="0 0 1"/>
      <limit lower="-3.14" upper="3.14" effort="10" velocity="1"/>
    </joint>

    <!-- ================= WRIST ================= -->
    <link name="wrist_link">
      <visual>
        <origin xyz="0 0 0.2"/>
        <geometry>
          <box size="0.4 0.4 0.4"/>
        </geometry>
        <material name="blue">
          <color rgba="0 0 1 1"/>
        </material>
      </visual>

      <collision>
        <origin xyz="0 0 0.2"/>
        <geometry>
          <box size="0.4 0.4 0.4"/>
        </geometry>
      </collision>

      <inertial>
        <mass value="0.5"/>
        <origin xyz="0 0 0.2"/>
        <inertia
          ixx="0.01" ixy="0.0" ixz="0.0"
          iyy="0.01" iyz="0.0"
          izz="0.01"/>
      </inertial>
    </link>

    <joint name="wrist_joint" type="revolute">
      <parent link="elbow_link"/>
      <child link="wrist_link"/>
      <origin xyz="0 0 0.4"/>
      <axis xyz="1 0 0"/>
      <limit lower="-1.57" upper="1.57" effort="10" velocity="1"/>
    </joint>

  </xacro:macro>

</robot>